Workbook

Sheet CPI Inflation_Case Study
A1: Sector | B1: Year | C1: Month | D1: Cereals and products | E1: Meat and fish | F1: Egg | G1: Milk and products | H1: Oils and fats | I1: Fruits | J1: Vegetables | K1: Pulses and products | L1: Sugar and Confectionery | M1: Spices | N1: Non-alcoholic beverages | O1: Prepared meals, snacks, sweets etc. | P1: Food and beverages | Q1: Pan, tobacco and intoxicants | R1: Clothing | S1: Footwear | T1: Clothing and footwear | U1: Housing | V1: Fuel and light | W1: Household goods and services | X1: Health | Y1: Transport and communication | Z1: Recreation and amusement | AA1: Education | AB1: Personal care and effects | AC1: Miscellaneous | AD1: General index
A2: Rural | B2: 2013 | C2: January | D2: 107.5 | E2: 106.3 | F2: 108.1 | G2: 104.9 | H2: 106.1 | I2: 103.9 | J2: 101.9 | K2: 106.1 | L2: 106.8 | M2: 103.1 | N2: 104.8 | O2: 106.7 | P2: 105.5 | Q2: 105.1 | R2: 106.5 | S2: 105.8 | T2: 106.4 | U2: NA | V2: 105.5 | W2: 104.8 | X2: 104 | Y2: 103.3 | Z2: 103.4 | AA2: 103.8 | AB2: 104.7 | AC2: 104 | AD2: 105.1
A3: Urban | B3: 2013 | C3: January | D3: 110.5 | E3: 109.1 | F3: 113 | G3: 103.6 | H3: 103.4 | I3: 102.3 | J3: 102.9 | K3: 105.8 | L3: 105.1 | M3: 101.8 | N3: 105.1 | O3: 107.9 | P3: 105.9 | Q3: 105.2 | R3: 105.9 | S3: 105 | T3: 105.8 | U3: 100.3 | V3: 105.4 | W3: 104.8 | X3: 104.1 | Y3: 103.2 | Z3: 102.9 | AA3: 103.5 | AB3: 104.3 | AC3: 103.7 | AD3: 104
A4: Rural+Urban | B4: 2013 | C4: January | D4: 108.4 | E4: 107.3 | F4: 110 | G4: 104.4 | H4: 105.1 | I4: 103.2 | J4: 102.2 | K4: 106 | L4: 106.2 | M4: 102.7 | N4: 104.9 | O4: 107.3 | P4: 105.6 | Q4: 105.1 | R4: 106.3 | S4: 105.5 | T4: 106.2 | U4: 100.3 | V4: 105.5 | W4: 104.8 | X4: 104 | Y4: 103.2 | Z4: 103.1 | AA4: 103.6 | AB4: 104.5 | AC4: 103.9 | AD4: 104.6
A5: Rural | B5: 2013 | C5: February | D5: 109.2 | E5: 108.7 | F5: 110.2 | G5: 105.4 | H5: 106.7 | I5: 104 | J5: 102.4 | K5: 105.9 | L5: 105.7 | M5: 103.1 | N5: 105.1 | O5: 107.7 | P5: 106.3 | Q5: 105.6 | R5: 107.1 | S5: 106.3 | T5: 107 | U5: NA | V5: 106.2 | W5: 105.2 | X5: 104.4 | Y5: 103.9 | Z5: 104 | AA5: 104.1 | AB5: 104.6 | AC5: 104.4 | AD5: 105.8
A6: Urban | B6: 2013 | C6: February | D6: 112.9 | E6: 112.9 | F6: 116.9 | G6: 104 | H6: 103.5 | I6: 103.1 | J6: 104.9 | K6: 104.1 | L6: 103.8 | M6: 102.3 | N6: 106 | O6: 109 | P6: 107.2 | Q6: 106 | R6: 106.6 | S6: 105.5 | T6: 106.4 | U6: 100.4 | V6: 105.7 | W6: 105.2 | X6: 104.7 | Y6: 104.4 | Z6: 103.3 | AA6: 103.7 | AB6: 104.3 | AC6: 104.3 | AD6: 104.7
A7: Rural+Urban | B7: 2013 | C7: February | D7: 110.4 | E7: 110.2 | F7: 112.8 | G7: 104.9 | H7: 105.5 | I7: 103.6 | J7: 103.2 | K7: 105.3 | L7: 105.1 | M7: 102.8 | N7: 105.5 | O7: 108.3 | P7: 106.6 | Q7: 105.7 | R7: 106.9 | S7: 106 | T7: 106.8 | U7: 100.4 | V7: 106 | W7: 105.2 | X7: 104.5 | Y7: 104.2 | Z7: 103.6 | AA7: 103.9 | AB7: 104.5 | AC7: 104.4 | AD7: 105.3
A8: Rural | B8: 2013 | C8: March | D8: 110.2 | E8: 108.8 | F8: 109.9 | G8: 105.6 | H8: 106.2 | I8: 105.7 | J8: 101.4 | K8: 105.7 | L8: 105 | M8: 103.3 | N8: 105.6 | O8: 108.2 | P8: 106.6 | Q8: 106.5 | R8: 107.6 | S8: 106.8 | T8: 107.5 | U8: NA | V8: 106.1 | W8: 105.6 | X8: 104.7 | Y8: 104.6 | Z8: 104 | AA8: 104.3 | AB8: 104.3 | AC8: 104.6 | AD8: 106
A9: Urban | B9: 2013 | C9: March | D9: 113.9 | E9: 111.4 | F9: 113.2 | G9: 104.3 | H9: 102.7 | I9: 104.9 | J9: 103.8 | K9: 103.5 | L9: 102.6 | M9: 102.4 | N9: 107 | O9: 109.8 | P9: 107.3 | Q9: 106.8 | R9: 107.2 | S9: 106 | T9: 107 | U9: 100.4 | V9: 106 | W9: 105.7 | X9: 105.2 | Y9: 105.5 | Z9: 103.5 | AA9: 103.8 | AB9: 104.2 | AC9: 104.9 | AD9: 105
A10: Rural+Urban | B10: 2013 | C10: March | D10: 111.4 | E10: 109.7 | F10: 111.2 | G10: 105.1 | H10: 104.9 | I10: 105.3 | J10: 102.2 | K10: 105 | L10: 104.2 | M10: 103 | N10: 106.2 | O10: 108.9 | P10: 106.9 | Q10: 106.6 | R10: 107.4 | S10: 106.5 | T10: 107.3 | U10: 100.4 | V10: 106.1 | W10: 105.6 | X10: 104.9 | Y10: 105.1 | Z10: 103.7 | AA10: 104 | AB10: 104.3 | AC10: 104.7 | AD10: 105.5
A11: Rural | B11: 2013 | C11: April | D11: 110.2 | E11: 109.5 | F11: 106.9 | G11: 106.3 | H11: 105.7 | I11: 108.3 | J11: 103.4 | K11: 105.7 | L11: 104.2 | M11: 103.2 | N11: 106.5 | O11: 108.8 | P11: 107.1 | Q11: 107.1 | R11: 108.1 | S11: 107.4 | T11: 108 | U11: NA | V11: 106.5 | W11: 106.1 | X11: 105.1 | Y11: 104.4 | Z11: 104.5 | AA11: 104.8 | AB11: 102.7 | AC11: 104.6 | AD11: 106.4
A12: Urban | B12: 2013 | C12: April | D12: 114.6 | E12: 113.4 | F12: 106 | G12: 104.7 | H12: 102.1 | I12: 109.5 | J12: 109.7 | K12: 104.6 | L12: 102 | M12: 103.5 | N12: 108.2 | O12: 110.6 | P12: 108.8 | Q12: 108.5 | R12: 107.9 | S12: 106.4 | T12: 107.7 | U12: 100.5 | V12: 106.4 | W12: 106.5 | X12: 105.7 | Y12: 105 | Z12: 104 | AA12: 105.2 | AB12: 103.2 | AC12: 105.1 | AD12: 105.7
A13: Rural+Urban | B13: 2013 | C13: April | D13: 111.6 | E13: 110.9 | F13: 106.6 | G13: 105.7 | H13: 104.4 | I13: 108.9 | J13: 105.5 | K13: 105.3 | L13: 103.5 | M13: 103.3 | N13: 107.2 | O13: 109.6 | P13: 107.7 | Q13: 107.5 | R13: 108 | S13: 107 | T13: 107.9 | U13: 100.5 | V13: 106.5 | W13: 106.3 | X13: 105.3 | Y13: 104.7 | Z13: 104.2 | AA13: 105 | AB13: 102.9 | AC13: 104.8 | AD13: 106.1
A14: Rural | B14: 2013 | C14: May | D14: 110.9 | E14: 109.8 | F14: 105.9 | G14: 107.5 | H14: 105.3 | I14: 108.1 | J14: 107.3 | K14: 106.1 | L14: 103.7 | M14: 104 | N14: 107.4 | O14: 109.9 | P14: 108.1 | Q14: 108.1 | R14: 108.8 | S14: 107.9 | T14: 108.6 | U14: NA | V14: 107.5 | W14: 106.8 | X14: 105.7 | Y14: 104.1 | Z14: 105 | AA14: 105.5 | AB14: 102.1 | AC14: 104.8 | AD14: 107.2
A15: Urban | B15: 2013 | C15: May | D15: 115.4 | E15: 114.2 | F15: 102.7 | G15: 105.5 | H15: 101.5 | I15: 110.6 | J15: 123.7 | K15: 105.2 | L15: 101.9 | M15: 105 | N15: 109.1 | O15: 111.3 | P15: 111.1 | Q15: 109.8 | R15: 108.5 | S15: 106.7 | T15: 108.3 | U15: 100.5 | V15: 107.2 | W15: 107.1 | X15: 106.2 | Y15: 103.9 | Z15: 104.6 | AA15: 105.7 | AB15: 102.6 | AC15: 104.9 | AD15: 106.6
A16: Rural+Urban | B16: 2013 | C16: May | D16: 112.3 | E16: 111.3 | F16: 104.7 | G16: 106.8 | H16: 103.9 | I16: 109.3 | J16: 112.9 | K16: 105.8 | L16: 103.1 | M16: 104.3 | N16: 108.1 | O16: 110.5 | P16: 109.2 | Q16: 108.6 | R16: 108.7 | S16: 107.4 | T16: 108.5 | U16: 100.5 | V16: 107.4 | W16: 106.9 | X16: 105.9 | Y16: 104 | Z16: 104.8 | AA16: 105.6 | AB16: 102.3 | AC16: 104.8 | AD16: 106.9
A17: Rural | B17: 2013 | C17: June | D17: 112.3 | E17: 112.1 | F17: 108.1 | G17: 108.3 | H17: 105.9 | I17: 109.2 | J17: 118 | K17: 106.8 | L17: 104.1 | M17: 105.4 | N17: 108.2 | O17: 111 | P17: 110.6 | Q17: 109 | R17: 109.7 | S17: 108.8 | T17: 109.5 | U17: NA | V17: 108.5 | W17: 107.5 | X17: 106.3 | Y17: 105 | Z17: 105.6 | AA17: 106.5 | AB17: 102.5 | AC17: 105.5 | AD17: 108.9
A18: Urban | B18: 2013 | C18: June | D18: 117 | E18: 120.1 | F18: 112.5 | G18: 107.3 | H18: 101.3 | I18: 112.4 | J18: 143.6 | K18: 105.4 | L18: 101.4 | M18: 106.4 | N18: 110 | O18: 112.2 | P18: 115 | Q18: 110.9 | R18: 109.2 | S18: 107.2 | T18: 108.9 | U18: 106.6 | V18: 108 | W18: 107.7 | X18: 106.5 | Y18: 105.2 | Z18: 105.2 | AA18: 108.1 | AB18: 103.3 | AC18: 106.1 | AD18: 109.7
A19: Rural+Urban | B19: 2013 | C19: June | D19: 113.8 | E19: 114.9 | F19: 109.8 | G19: 107.9 | H19: 104.2 | I19: 110.7 | J19: 126.7 | K19: 106.3 | L19: 103.2 | M19: 105.7 | N19: 109 | O19: 111.6 | P19: 112.2 | Q19: 109.5 | R19: 109.5 | S19: 108.1 | T19: 109.3 | U19: 106.6 | V19: 108.3 | W19: 107.6 | X19: 106.4 | Y19: 105.1 | Z19: 105.4 | AA19: 107.4 | AB19: 102.8 | AC19: 105.8 | AD19: 109.3
A20: Rural | B20: 2013 | C20: July | D20: 113.4 | E20: 114.9 | F20: 110.5 | G20: 109.3 | H20: 106.2 | I20: 110.3 | J20: 129.2 | K20: 107.1 | L20: 104.3 | M20: 106.4 | N20: 109.1 | O20: 112.1 | P20: 113.1 | Q20: 109.8 | R20: 110.5 | S20: 109.5 | T20: 110.3 | U20: NA | V20: 109.5 | W20: 108.3 | X20: 106.9 | Y20: 106.8 | Z20: 106.4 | AA20: 107.8 | AB20: 102.5 | AC20: 106.5 | AD20: 110.7
A21: Urban | B21: 2013 | C21: July | D21: 117.8 | E21: 119.2 | F21: 114 | G21: 108.3 | H21: 101.1 | I21: 113.2 | J21: 160.9 | K21: 105.1 | L21: 101.3 | M21: 107.5 | N21: 110.4 | O21: 113.1 | P21: 117.5 | Q21: 111.7 | R21: 109.8 | S21: 107.8 | T21: 109.5 | U21: 107.7 | V21: 108.6 | W21: 108.1 | X21: 107.1 | Y21: 107.3 | Z21: 105.9 | AA21: 110.1 | AB21: 103.2 | AC21: 107.3 | AD21: 111.4
A22: Rural+Urban | B22: 2013 | C22: July | D22: 114.8 | E22: 116.4 | F22: 111.9 | G22: 108.9 | H22: 104.3 | I22: 111.7 | J22: 140 | K22: 106.4 | L22: 103.3 | M22: 106.8 | N22: 109.6 | O22: 112.6 | P22: 114.7 | Q22: 110.3 | R22: 110.2 | S22: 108.8 | T22: 110 | U22: 107.7 | V22: 109.2 | W22: 108.2 | X22: 107 | Y22: 107.1 | Z22: 106.1 | AA22: 109.1 | AB22: 102.8 | AC22: 106.9 | AD22: 111
A23: Rural | B23: 2013 | C23: August | D23: 114.3 | E23: 115.4 | F23: 111.1 | G23: 110 | H23: 106.4 | I23: 110.8 | J23: 138.9 | K23: 107.4 | L23: 104.1 | M23: 106.9 | N23: 109.7 | O23: 112.6 | P23: 114.9 | Q23: 110.7 | R23: 111.3 | S23: 110.2 | T23: 111.1 | U23: NA | V23: 109.9 | W23: 108.7 | X23: 107.5 | Y23: 107.8 | Z23: 106.8 | AA23: 108.7 | AB23: 105 | AC23: 107.5 | AD23: 112.1
A24: Urban | B24: 2013 | C24: August | D24: 118.3 | E24: 120.4 | F24: 112.7 | G24: 108.9 | H24: 101.1 | I24: 108.7 | J24: 177 | K24: 104.7 | L24: 101 | M24: 108.5 | N24: 110.9 | O24: 114.3 | P24: 119.6 | Q24: 112.4 | R24: 110.6 | S24: 108.3 | T24: 110.2 | U24: 108.9 | V24: 109.3 | W24: 108.7 | X24: 107.6 | Y24: 108.1 | Z24: 106.5 | AA24: 110.8 | AB24: 106 | AC24: 108.3 | AD24: 112.7
A25: Rural+Urban | B25: 2013 | C25: August | D25: 115.6 | E25: 117.2 | F25: 111.7 | G25: 109.6 | H25: 104.5 | I25: 109.8 | J25: 151.8 | K25: 106.5 | L25: 103.1 | M25: 107.4 | N25: 110.2 | O25: 113.4 | P25: 116.6 | Q25: 111.2 | R25: 111 | S25: 109.4 | T25: 110.7 | U25: 108.9 | V25: 109.7 | W25: 108.7 | X25: 107.5 | Y25: 108 | Z25: 106.6 | AA25: 109.9 | AB25: 105.4 | AC25: 107.9 | AD25: 112.4
A26: Rural | B26: 2013 | C26: September | D26: 115.4 | E26: 115.7 | F26: 111.7 | G26: 111 | H26: 107.4 | I26: 110.9 | J26: 154 | K26: 108.1 | L26: 104.2 | M26: 107.9 | N26: 110.4 | O26: 114 | P26: 117.8 | Q26: 111.7 | R26: 112.7 | S26: 111.4 | T26: 112.5 | U26: NA | V26: 111.1 | W26: 109.6 | X26: 108.3 | Y26: 109.3 | Z26: 107.7 | AA26: 109.8 | AB26: 106.7 | AC26: 108.7 | AD26: 114.2
A27: Urban | B27: 2013 | C27: September | D27: 118.6 | E27: 119.1 | F27: 113.2 | G27: 109.6 | H27: 101.7 | I27: 103.2 | J27: 174.3 | K27: 105.1 | L27: 100.8 | M27: 109.1 | N27: 111.1 | O27: 115.4 | P27: 119.2 | Q27: 112.9 | R27: 111.4 | S27: 109 | T27: 111.1 | U27: 109.7 | V27: 109.5 | W27: 109.6 | X27: 107.9 | Y27: 110.4 | Z27: 107.4 | AA27: 111.2 | AB27: 106.9 | AC27: 109.4 | AD27: 113.2
A28: Rural+Urban | B28: 2013 | C28: September | D28: 116.4 | E28: 116.9 | F28: 112.3 | G28: 110.5 | H28: 105.3 | I28: 107.3 | J28: 160.9 | K28: 107.1 | L28: 103.1 | M28: 108.3 | N28: 110.7 | O28: 114.6 | P28: 118.3 | Q28: 112 | R28: 112.2 | S28: 110.4 | T28: 111.9 | U28: 109.7 | V28: 110.5 | W28: 109.6 | X28: 108.1 | Y28: 109.9 | Z28: 107.5 | AA28: 110.6 | AB28: 106.8 | AC28: 109 | AD28: 113.7
A29: Rural | B29: 2013 | C29: October | D29: 116.3 | E29: 115.4 | F29: 112.6 | G29: 111.7 | H29: 107.7 | I29: 113.2 | J29: 164.9 | K29: 108.3 | L29: 103.9 | M29: 108.2 | N29: 111.1 | O29: 114.9 | P29: 119.8 | Q29: 112.2 | R29: 113.6 | S29: 112.3 | T29: 113.4 | U29: NA | V29: 111.6 | W29: 110.4 | X29: 108.9 | Y29: 109.3 | Z29: 108.3 | AA29: 110.2 | AB29: 107.5 | AC29: 109.1 | AD29: 115.5
A30: Urban | B30: 2013 | C30: October | D30: 118.9 | E30: 118.1 | F30: 114.5 | G30: 110.4 | H30: 102.3 | I30: 106.2 | J30: 183.5 | K30: 105.3 | L30: 100.2 | M30: 109.6 | N30: 111.4 | O30: 116 | P30: 120.8 | Q30: 113.5 | R30: 112.5 | S30: 109.7 | T30: 112 | U30: 110.5 | V30: 109.7 | W30: 110.2 | X30: 108.2 | Y30: 109.7 | Z30: 108 | AA30: 111.3 | AB30: 107.3 | AC30: 109.4 | AD30: 114
A31: Rural+Urban | B31: 2013 | C31: October | D31: 117.1 | E31: 116.3 | F31: 113.3 | G31: 111.2 | H31: 105.7 | I31: 109.9 | J31: 171.2 | K31: 107.3 | L31: 102.7 | M31: 108.7 | N31: 111.2 | O31: 115.4 | P31: 120.2 | Q31: 112.5 | R31: 113.2 | S31: 111.2 | T31: 112.8 | U31: 110.5 | V31: 110.9 | W31: 110.3 | X31: 108.6 | Y31: 109.5 | Z31: 108.1 | AA31: 110.8 | AB31: 107.4 | AC31: 109.2 | AD31: 114.8
A32: Rural | B32: 2013 | C32: November | D32: 117.3 | E32: 114.9 | F32: 116.2 | G32: 112.8 | H32: 108.9 | I32: 116.6 | J32: 178.1 | K32: 109.1 | L32: 103.6 | M32: 109 | N32: 111.8 | O32: 116 | P32: 122.5 | Q32: 112.8 | R32: 114.6 | S32: 113.1 | T32: 114.4 | U32: NA | V32: 112.6 | W32: 111.3 | X32: 109.7 | Y32: 109.6 | Z32: 108.7 | AA32: 111 | AB32: 108.2 | AC32: 109.8 | AD32: 117.4
A33: Urban | B33: 2013 | C33: November | D33: 119.8 | E33: 116.3 | F33: 122.6 | G33: 112 | H33: 103.2 | I33: 110 | J33: 192.8 | K33: 106.3 | L33: 99.5 | M33: 110.3 | N33: 111.8 | O33: 117.1 | P33: 122.9 | Q33: 114.1 | R33: 113.5 | S33: 110.3 | T33: 113 | U33: 111.1 | V33: 110 | W33: 110.9 | X33: 108.6 | Y33: 109.5 | Z33: 108.5 | AA33: 111.3 | AB33: 107.9 | AC33: 109.6 | AD33: 115
A34: Rural+Urban | B34: 2013 | C34: November | D34: 118.1 | E34: 115.4 | F34: 118.7 | G34: 112.5 | H34: 106.8 | I34: 113.5 | J34: 183.1 | K34: 108.2 | L34: 102.2 | M34: 109.4 | N34: 111.8 | O34: 116.5 | P34: 122.6 | Q34: 113.1 | R34: 114.2 | S34: 111.9 | T34: 113.8 | U34: 111.1 | V34: 111.6 | W34: 111.1 | X34: 109.3 | Y34: 109.5 | Z34: 108.6 | AA34: 111.2 | AB34: 108.1 | AC34: 109.7 | AD34: 116.3
A35: Rural | B35: 2013 | C35: December | D35: 118.4 | E35: 115.9 | F35: 120.4 | G35: 113.8 | H35: 109.5 | I35: 115.5 | J35: 145.7 | K35: 109.5 | L35: 102.9 | M35: 109.8 | N35: 112.1 | O35: 116.8 | P35: 118.7 | Q35: 113.6 | R35: 115.8 | S35: 114 | T35: 115.5 | U35: NA | V35: 112.8 | W35: 112.1 | X35: 110.1 | Y35: 109.9 | Z35: 109.2 | AA35: 111.6 | AB35: 108.1 | AC35: 110.1 | AD35: 115.5
A36: Urban | B36: 2013 | C36: December | D36: 120.5 | E36: 118.1 | F36: 128.5 | G36: 112.8 | H36: 103.4 | I36: 110.7 | J36: 144.8 | K36: 107.1 | L36: 98.6 | M36: 111.9 | N36: 112.1 | O36: 118.1 | P36: 117.8 | Q36: 115 | R36: 114.2 | S36: 110.9 | T36: 113.7 | U36: 110.7 | V36: 110.4 | W36: 111.3 | X36: 109 | Y36: 109.7 | Z36: 108.9 | AA36: 111.4 | AB36: 107.7 | AC36: 109.8 | AD36: 113.3
A37: Rural+Urban | B37: 2013 | C37: December | D37: 119.1 | E37: 116.7 | F37: 123.5 | G37: 113.4 | H37: 107.3 | I37: 113.3 | J37: 145.4 | K37: 108.7 | L37: 101.5 | M37: 110.5 | N37: 112.1 | O37: 117.4 | P37: 118.4 | Q37: 114 | R37: 115.2 | S37: 112.7 | T37: 114.8 | U37: 110.7 | V37: 111.9 | W37: 111.7 | X37: 109.7 | Y37: 109.8 | Z37: 109 | AA37: 111.5 | AB37: 107.9 | AC37: 110 | AD37: 114.5
A38: Rural | B38: 2014 | C38: January | D38: 118.9 | E38: 117.1 | F38: 120.5 | G38: 114.4 | H38: 109 | I38: 115.5 | J38: 123.9 | K38: 109.6 | L38: 101.8 | M38: 110.2 | N38: 112.4 | O38: 117.3 | P38: 116 | Q38: 114 | R38: 116.5 | S38: 114.5 | T38: 116.2 | U38: NA | V38: 113 | W38: 112.6 | X38: 110.6 | Y38: 110.5 | Z38: 109.6 | AA38: 111.8 | AB38: 108.3 | AC38: 110.6 | AD38: 114.2
A39: Urban | B39: 2014 | C39: January | D39: 121.2 | E39: 122 | F39: 129.9 | G39: 113.6 | H39: 102.9 | I39: 112.1 | J39: 118.9 | K39: 107.5 | L39: 96.9 | M39: 112.7 | N39: 112.1 | O39: 119 | P39: 115.5 | Q39: 115.7 | R39: 114.8 | S39: 111.3 | T39: 114.3 | U39: 111.6 | V39: 111 | W39: 111.9 | X39: 109.7 | Y39: 110.8 | Z39: 109.8 | AA39: 111.5 | AB39: 108 | AC39: 110.5 | AD39: 112.9
A40: Rural+Urban | B40: 2014 | C40: January | D40: 119.6 | E40: 118.8 | F40: 124.1 | G40: 114.1 | H40: 106.8 | I40: 113.9 | J40: 122.2 | K40: 108.9 | L40: 100.2 | M40: 111 | N40: 112.3 | O40: 118.1 | P40: 115.8 | Q40: 114.5 | R40: 115.8 | S40: 113.2 | T40: 115.4 | U40: 111.6 | V40: 112.2 | W40: 112.3 | X40: 110.3 | Y40: 110.7 | Z40: 109.7 | AA40: 111.6 | AB40: 108.2 | AC40: 110.6 | AD40: 113.6
...

Sheet Sheet1
A1: Category | B1: New Category Mapped | C1: Special Categories | E1: Problem 1 | G1: Problem 2 | I1: Problem 3 | K1: Problem 4 | M1: Problem 5
A2: Cereals and products | B2: Food | C2: Food | E2: Time Period - May'23 | G2: YoY | I2: ending May'23 | K2: Impact of Covid on inflation | M2: Imported oil prices | N2: take it from Google
A3: Meat and fish | B3: Food | C3: Food | G3: Rural+Urban | I3: Jun'22 to May'23 - Mom% | K3: Mar'20 | M3: Jan'21
A4: Egg | B4: Food | C4: Food | G4: starting from 2017 | I4: Only food category | M4: May'23
A5: Milk and products | B5: Food | C5: Food | G5: GI | I5: Rural, Urban and Rural + Urban | M5: MoM%
A6: Oils and fats | B6: Food | C6: Food | G6: we don't have complete data for 2023
A7: Fruits | B7: Food | C7: Food | G7: so we skip 2023 and take data till 2022
A8: Vegetables | B8: Food | C8: Food
A9: Pulses and products | B9: Food | C9: Food
A10: Sugar and Confectionery | B10: Food | C10: Food
A11: Spices | B11: Food | C11: Food
A12: Non-alcoholic beverages | B12: Luxury
A13: Prepared meals, snacks, sweets etc. | B13: Food | C13: Food
A14: Food and beverages | B14: Food | C14: Food
A15: Pan, tobacco and intoxicants | B15: Luxury
A16: Clothing | B16: Apparel
A17: Footwear | B17: Apparel
A18: Clothing and footwear | B18: Apparel
A19: Housing | B19: Housing | C19: Essential services
A20: Fuel and light | B20: Fuel and light | C20: Essential services
A21: Household goods and services | B21: Housing | C21: Essential services
A22: Health | B22: Health | C22: Health
A23: Transport and communication | B23: Transport | C23: Essential services
A24: Recreation and amusement | B24: Recreation and amusement
A25: Education | B25: Education | C25: Essential services
A26: Personal care and effects | B26: Personal care and effects
A27: Miscellaneous | B27: Misc
A28: General index | B28: GI

Sheet Problem.1
A1: Sector | B1: Year | C1: Month | D1: Cereals and products | E1: Meat and fish | F1: Egg | G1: Milk and products | H1: Oils and fats | I1: Fruits | J1: Vegetables | K1: Pulses and products | L1: Sugar and Confectionery | M1: Spices | N1: Non-alcoholic beverages | O1: Prepared meals, snacks, sweets etc. | P1: Food and beverages | Q1: Pan, tobacco and intoxicants | R1: Clothing | S1: Footwear | T1: Clothing and footwear | U1: Housing | V1: Fuel and light | W1: Household goods and services | X1: Health | Y1: Transport and communication | Z1: Recreation and amusement | AA1: Education | AB1: Personal care and effects | AC1: Miscellaneous | AD1: General index
A2: Rural | B2: 2023 | C2: May | D2: 173.2 | E2: 211.5 | F2: 171 | G2: 179.6 | H2: 173.3 | I2: 169 | J2: 148.7 | K2: 174.9 | L2: 121.9 | M2: 221 | N2: 178.7 | O2: 191.1 | P2: 176.8 | Q2: 199.9 | R2: 191.2 | S2: 187.9 | T2: 190.8 | U2: - | V2: 182.5 | W2: 179.8 | X2: 187.8 | Y2: 169.7 | Z2: 173.8 | AA2: 180.3 | AB2: 184.9 | AC2: 179.5 | AD2: 179.8
A3: Urban | B3: 2023 | C3: May | D3: 174.7 | E3: 219.4 | F3: 176.7 | G3: 179.4 | H3: 164.4 | I3: 175.8 | J3: 185 | K3: 176.9 | L3: 124.2 | M3: 211.9 | N3: 165.9 | O3: 197.7 | P3: 183.1 | Q3: 204.2 | R3: 181.3 | S3: 168.1 | T3: 179.3 | U3: 175.6 | V3: 183.4 | W3: 170.1 | X3: 182.2 | Y3: 160.4 | Z3: 169.2 | AA3: 174.8 | AB3: 185.6 | AC3: 171.6 | AD3: 178.2
A4: Rural+Urban | B4: 2023 | C4: May | D4: 173.7 | E4: 214.3 | F4: 173.2 | G4: 179.5 | H4: 170 | I4: 172.2 | J4: 161 | K4: 175.6 | L4: 122.7 | M4: 218 | N4: 173.4 | O4: 194.2 | P4: 179.1 | Q4: 201 | R4: 187.3 | S4: 179.7 | T4: 186.2 | U4: 175.6 | V4: 182.8 | W4: 175.2 | X4: 185.7 | Y4: 164.8 | Z4: 171.2 | AA4: 177.1 | AB4: 185.2 | AC4: 175.7 | AD4: 179.1
A6: May'23
A7: Category | B7: Rural | C7: Urban | D7: Rural+Urban | E7: New Category Mapped | H7: New Category Mapped | I7: Rural | J7: Urban | K7: Rural+Urban | L7: Rural% | M7: Urban% | N7: Rural+Urban%
A8: Cereals and products | B8: 173.2 | C8: 174.7 | D8: 173.7 | E8: Food | H8: {=_xlfn.UNIQUE(E8:E34)} -> Food | I8: =SUMIF($E$8:$E$34,$H8,B$8:B$34) -> 2112 | J8: =SUMIF($E$8:$E$34,$H8,C$8:C$34) -> 2169.2 | K8: =SUMIF($E$8:$E$34,$H8,D$8:D$34) -> 2133.5 | L8: =I8/I$20 -> 0.46945852 | M8: =J8/J$20 -> 0.46740934 | N8: =K8/K$20 -> 0.45838347
A9: Meat and fish | B9: 211.5 | C9: 219.4 | D9: 214.3 | E9: Food | H9: Luxury | I9: =SUMIF($E$8:$E$34,$H9,B$8:B$34) -> 378.6 | J9: =SUMIF($E$8:$E$34,$H9,C$8:C$34) -> 370.1 | K9: =SUMIF($E$8:$E$34,$H9,D$8:D$34) -> 374.4 | L9: =I9/I$20 -> 0.084155775 | M9: =J9/J$20 -> 0.079747463 | N9: =K9/K$20 -> 0.080440014
A10: Egg | B10: 171 | C10: 176.7 | D10: 173.2 | E10: Food | H10: Apparel | I10: =SUMIF($E$8:$E$34,$H10,B$8:B$34) -> 569.9 | J10: =SUMIF($E$8:$E$34,$H10,C$8:C$34) -> 528.7 | K10: =SUMIF($E$8:$E$34,$H10,D$8:D$34) -> 553.2 | L10: =I10/I$20 -> 0.12667823 | M10: =J10/J$20 -> 0.11392187 | N10: =K10/K$20 -> 0.11885528
A11: Milk and products | B11: 179.6 | C11: 179.4 | D11: 179.5 | E11: Food | H11: Housing | I11: =SUMIF($E$8:$E$34,$H11,B$8:B$34) -> 179.8 | J11: =SUMIF($E$8:$E$34,$H11,C$8:C$34) -> 345.7 | K11: =SUMIF($E$8:$E$34,$H11,D$8:D$34) -> 350.8 | L11: =I11/I$20 -> 0.039966213 | M11: =J11/J$20 -> 0.074489862 | N11: =K11/K$20 -> 0.075369543
A12: Oils and fats | B12: 173.3 | C12: 164.4 | D12: 170 | E12: Food | H12: Fuel and light | I12: =SUMIF($E$8:$E$34,$H12,B$8:B$34) -> 182.5 | J12: =SUMIF($E$8:$E$34,$H12,C$8:C$34) -> 183.4 | K12: =SUMIF($E$8:$E$34,$H12,D$8:D$34) -> 182.8 | L12: =I12/I$20 -> 0.040566373 | M12: =J12/J$20 -> 0.039518197 | N12: =K12/K$20 -> 0.039274665
A13: Fruits | B13: 169 | C13: 175.8 | D13: 172.2 | E13: Food | H13: Health | I13: =SUMIF($E$8:$E$34,$H13,B$8:B$34) -> 187.8 | J13: =SUMIF($E$8:$E$34,$H13,C$8:C$34) -> 182.2 | K13: =SUMIF($E$8:$E$34,$H13,D$8:D$34) -> 185.7 | L13: =I13/I$20 -> 0.041744465 | M13: =J13/J$20 -> 0.039259626 | N13: =K13/K$20 -> 0.039897731
A14: Vegetables | B14: 148.7 | C14: 185 | D14: 161 | E14: Food | H14: Transport | I14: =SUMIF($E$8:$E$34,$H14,B$8:B$34) -> 169.7 | J14: =SUMIF($E$8:$E$34,$H14,C$8:C$34) -> 160.4 | K14: =SUMIF($E$8:$E$34,$H14,D$8:D$34) -> 164.8 | L14: =I14/I$20 -> 0.03772117 | M14: =J14/J$20 -> 0.034562262 | N14: =K14/K$20 -> 0.035407356
A15: Pulses and products | B15: 174.9 | C15: 176.9 | D15: 175.6 | E15: Food | H15: Recreation and amusement | I15: =SUMIF($E$8:$E$34,$H15,B$8:B$34) -> 173.8 | J15: =SUMIF($E$8:$E$34,$H15,C$8:C$34) -> 169.2 | K15: =SUMIF($E$8:$E$34,$H15,D$8:D$34) -> 171.2 | L15: =I15/I$20 -> 0.038632524 | M15: =J15/J$20 -> 0.036458446 | N15: =K15/K$20 -> 0.036782399
A16: Sugar and Confectionery | B16: 121.9 | C16: 124.2 | D16: 122.7 | E16: Food | H16: Education | I16: =SUMIF($E$8:$E$34,$H16,B$8:B$34) -> 180.3 | J16: =SUMIF($E$8:$E$34,$H16,C$8:C$34) -> 174.8 | K16: =SUMIF($E$8:$E$34,$H16,D$8:D$34) -> 177.1 | L16: =I16/I$20 -> 0.040077354 | M16: =J16/J$20 -> 0.037665108 | N16: =K16/K$20 -> 0.038050017
A17: Spices | B17: 221 | C17: 211.9 | D17: 218 | E17: Food | H17: Personal care and effects | I17: =SUMIF($E$8:$E$34,$H17,B$8:B$34) -> 184.9 | J17: =SUMIF($E$8:$E$34,$H17,C$8:C$34) -> 185.6 | K17: =SUMIF($E$8:$E$34,$H17,D$8:D$34) -> 185.2 | L17: =I17/I$20 -> 0.041099849 | M17: =J17/J$20 -> 0.039992243 | N17: =K17/K$20 -> 0.039790306
A18: Non-alcoholic beverages | B18: 178.7 | C18: 165.9 | D18: 173.4 | E18: Luxury | H18: Misc | I18: =SUMIF($E$8:$E$34,$H18,B$8:B$34) -> 179.5 | J18: =SUMIF($E$8:$E$34,$H18,C$8:C$34) -> 171.6 | K18: =SUMIF($E$8:$E$34,$H18,D$8:D$34) -> 175.7 | L18: =I18/I$20 -> 0.039899529 | M18: =J18/J$20 -> 0.036975587 | N18: =K18/K$20 -> 0.037749227
A19: Prepared meals, snacks, sweets etc. | B19: 191.1 | C19: 197.7 | D19: 194.2 | E19: Food | H19: GI | I19: =SUMIF($E$8:$E$34,$H19,B$8:B$34) -> 179.8 | J19: =SUMIF($E$8:$E$34,$H19,C$8:C$34) -> 178.2 | K19: =SUMIF($E$8:$E$34,$H19,D$8:D$34) -> 179.1 | L19: - | M19: - | N19: -
A20: Food and beverages | B20: 176.8 | C20: 183.1 | D20: 179.1 | E20: Food | H20: Grand Total | I20: =SUM(I8:I18) -> 4498.8 | J20: =SUM(J8:J18) -> 4640.9 | K20: =SUM(K8:K18) -> 4654.4 | L20: =SUM(L8:L18) -> 1 | M20: =SUM(M8:M18) -> 1 | N20: =SUM(N8:N18) -> 1
A21: Pan, tobacco and intoxicants | B21: 199.9 | C21: 204.2 | D21: 201 | E21: Luxury
A22: Clothing | B22: 191.2 | C22: 181.3 | D22: 187.3 | E22: Apparel
A23: Footwear | B23: 187.9 | C23: 168.1 | D23: 179.7 | E23: Apparel | H23: New Category Mapped | I23: Rural% | J23: Urban% | K23: Rural+Urban%
A24: Clothing and footwear | B24: 190.8 | C24: 179.3 | D24: 186.2 | E24: Apparel | H24: Food | I24: 0.46945852 | J24: 0.46740934 | K24: 0.45838347
A25: Housing | B25: - | C25: 175.6 | D25: 175.6 | E25: Housing | H25: Luxury | I25: 0.084155775 | J25: 0.079747463 | K25: 0.080440014
A26: Fuel and light | B26: 182.5 | C26: 183.4 | D26: 182.8 | E26: Fuel and light | H26: Apparel | I26: 0.12667823 | J26: 0.11392187 | K26: 0.11885528
A27: Household goods and services | B27: 179.8 | C27: 170.1 | D27: 175.2 | E27: Housing | H27: Housing | I27: 0.039966213 | J27: 0.074489862 | K27: 0.075369543
A28: Health | B28: 187.8 | C28: 182.2 | D28: 185.7 | E28: Health | H28: Fuel and light | I28: 0.040566373 | J28: 0.039518197 | K28: 0.039274665
A29: Transport and communication | B29: 169.7 | C29: 160.4 | D29: 164.8 | E29: Transport | H29: Health | I29: 0.041744465 | J29: 0.039259626 | K29: 0.039897731
A30: Recreation and amusement | B30: 173.8 | C30: 169.2 | D30: 171.2 | E30: Recreation and amusement | H30: Transport | I30: 0.03772117 | J30: 0.034562262 | K30: 0.035407356
A31: Education | B31: 180.3 | C31: 174.8 | D31: 177.1 | E31: Education | H31: Recreation and amusement | I31: 0.038632524 | J31: 0.036458446 | K31: 0.036782399
A32: Personal care and effects | B32: 184.9 | C32: 185.6 | D32: 185.2 | E32: Personal care and effects | H32: Education | I32: 0.040077354 | J32: 0.037665108 | K32: 0.038050017
A33: Miscellaneous | B33: 179.5 | C33: 171.6 | D33: 175.7 | E33: Misc | H33: Personal care and effects | I33: 0.041099849 | J33: 0.039992243 | K33: 0.039790306
A34: General index | B34: 179.8 | C34: 178.2 | D34: 179.1 | E34: GI | H34: Misc | I34: 0.039899529 | J34: 0.036975587 | K34: 0.037749227
H35: GI | I35: - | J35: - | K35: -
H36: Grand Total | I36: 1 | J36: 1 | K36: 1

Sheet Problem.2
A1: Sector | B1: Year | C1: Month | D1: Cereals and products | E1: Meat and fish | F1: Egg | G1: Milk and products | H1: Oils and fats | I1: Fruits | J1: Vegetables | K1: Pulses and products | L1: Sugar and Confectionery | M1: Spices | N1: Non-alcoholic beverages | O1: Prepared meals, snacks, sweets etc. | P1: Food and beverages | Q1: Pan, tobacco and intoxicants | R1: Clothing | S1: Footwear | T1: Clothing and footwear | U1: Housing | V1: Fuel and light | W1: Household goods and services | X1: Health | Y1: Transport and communication | Z1: Recreation and amusement | AA1: Education | AB1: Personal care and effects | AC1: Miscellaneous | AD1: General index
A2: Rural+Urban | B2: 2017 | C2: January | D2: 132.8 | E2: 138.2 | F2: 132.2 | G2: 135.4 | H2: 119.1 | I2: 133 | J2: 119.4 | K2: 159.5 | L2: 115.6 | M2: 139.6 | N2: 126.6 | O2: 142.8 | P2: 133.1 | Q2: 143.8 | R2: 136.6 | S2: 130.2 | T2: 135.6 | U2: 129.6 | V2: 126.8 | W2: 129.4 | X2: 127.1 | Y2: 117 | Z2: 124.2 | AA2: 133.3 | AB2: 121.7 | AC2: 124.4 | AD2: 130.3
A3: Rural+Urban | B3: 2017 | C3: February | D3: 133.1 | E3: 138.8 | F3: 129.3 | G3: 135.8 | H3: 119.2 | I3: 135.3 | J3: 119.5 | K3: 152.2 | L3: 117.3 | M3: 138.7 | N3: 126.9 | O3: 143.2 | P3: 133 | Q3: 144.4 | R3: 136.8 | S3: 130.3 | T3: 135.9 | U3: 130.5 | V3: 127.9 | W3: 129.7 | X3: 127.4 | Y3: 117.4 | Z3: 124.6 | AA3: 133.4 | AB3: 122.6 | AC3: 124.8 | AD3: 130.6
A4: Rural+Urban | B4: 2017 | C4: March | D4: 133.3 | E4: 139 | F4: 128.6 | G4: 136.3 | H4: 118.8 | I4: 138.3 | J4: 120.5 | K4: 143.9 | L4: 118 | M4: 137.9 | N4: 127.2 | O4: 144 | P4: 133.1 | Q4: 145.1 | R4: 137.3 | S4: 130.6 | T4: 136.4 | U4: 131.1 | V4: 129.1 | W4: 130.1 | X4: 127.8 | Y4: 117.6 | Z4: 125 | AA4: 133.8 | AB4: 122.6 | AC4: 125.1 | AD4: 130.9
A5: Rural+Urban | B5: 2017 | C5: April | D5: 133 | E5: 139.4 | F5: 126.1 | G5: 137.2 | H5: 118.4 | I5: 139.9 | J5: 123.4 | K5: 140.9 | L5: 118.5 | M5: 136.5 | N5: 127.4 | O5: 144.2 | P5: 133.5 | Q5: 145.4 | R5: 138 | S5: 131.1 | T5: 137 | U5: 131.7 | V5: 129.8 | W5: 130.4 | X5: 128.1 | Y5: 116.6 | Z5: 125.1 | AA5: 134.5 | AB5: 123.1 | AC5: 125.1 | AD5: 131.1
A6: Rural+Urban | B6: 2017 | C6: May | D6: 132.9 | E6: 141.6 | F6: 126.3 | G6: 137.7 | H6: 118.1 | I6: 137.9 | J6: 125.6 | K6: 138.3 | L6: 119.4 | M6: 136 | N6: 127.6 | O6: 144.5 | P6: 133.7 | Q6: 146.2 | R6: 138.2 | S6: 131.4 | T6: 137.2 | U6: 132.1 | V6: 129.4 | W6: 130.9 | X6: 128.4 | Y6: 116.7 | Z6: 125.7 | AA6: 134.8 | AB6: 123 | AC6: 125.3 | AD6: 131.4
A7: Rural+Urban | B7: 2017 | C7: June | D7: 133.3 | E7: 145.5 | F7: 128.1 | G7: 138.1 | H7: 118.2 | I7: 139.2 | J7: 133.3 | K7: 136.2 | L7: 119.6 | M7: 135.3 | N7: 127.8 | O7: 144.9 | P7: 135.2 | Q7: 146.5 | R7: 138.5 | S7: 131.7 | T7: 137.5 | U7: 131.4 | V7: 128.8 | W7: 131.2 | X7: 128.5 | Y7: 116.5 | Z7: 125.9 | AA7: 135.4 | AB7: 123.4 | AC7: 125.5 | AD7: 132
A8: Rural+Urban | B8: 2017 | C8: July | D8: 133.6 | E8: 145.7 | F8: 129.6 | G8: 138.5 | H8: 118.1 | I8: 141.8 | J8: 159.5 | K8: 133.6 | L8: 120.5 | M8: 135.2 | N8: 128.5 | O8: 145.8 | P8: 139 | Q8: 148.2 | R8: 139.3 | S8: 132.1 | T8: 138.3 | U8: 132.6 | V8: 129.4 | W8: 131.9 | X8: 129.4 | Y8: 116 | Z8: 126.6 | AA8: 136.8 | AB8: 123.6 | AC8: 125.9 | AD8: 134.2
A9: Rural+Urban | B9: 2017 | C9: August | D9: 134.3 | E9: 143.4 | F9: 129.3 | G9: 139 | H9: 118.1 | I9: 145.5 | J9: 168.6 | K9: 132.7 | L9: 121.2 | M9: 135.6 | N9: 128.7 | O9: 146.8 | P9: 140.6 | Q9: 149.8 | R9: 140.3 | S9: 133 | T9: 139.3 | U9: 134.4 | V9: 129.8 | W9: 132.8 | X9: 130.2 | Y9: 117.3 | Z9: 127.3 | AA9: 137.6 | AB9: 124.5 | AC9: 126.8 | AD9: 135.4
A10: Rural+Urban | B10: 2017 | C10: September | D10: 134.7 | E10: 142.4 | F10: 130.2 | G10: 139.6 | H10: 118.4 | I10: 143 | J10: 156.6 | K10: 132.9 | L10: 121.5 | M10: 135.6 | N10: 128.8 | O10: 147.3 | P10: 139 | Q10: 150.8 | R10: 141.1 | S10: 133.4 | T10: 140 | U10: 135.7 | V10: 131 | W10: 133.3 | X10: 130.6 | Y10: 118.3 | Z10: 127.9 | AA10: 137.4 | AB10: 125.7 | AC10: 127.5 | AD10: 135.2
A11: Rural+Urban | B11: 2017 | C11: October | D11: 135.3 | E11: 142.2 | F11: 131.2 | G11: 140.6 | H11: 119 | I11: 141.5 | J11: 162.6 | K11: 132.3 | L11: 121.8 | M11: 136.3 | N11: 128.7 | O11: 148.1 | P11: 140.1 | Q11: 151.6 | R11: 142 | S11: 134.1 | T11: 140.8 | U11: 137.3 | V11: 132.2 | W11: 133.6 | X11: 131.3 | Y11: 117.8 | Z11: 128.4 | AA11: 137.9 | AB11: 126.2 | AC11: 127.7 | AD11: 136.1
A12: Rural+Urban | B12: 2017 | C12: November | D12: 135.7 | E12: 142.4 | F12: 142.9 | G12: 140.8 | H12: 119.2 | I12: 142.2 | J12: 173.8 | K12: 131.2 | L12: 123 | M12: 136.8 | N12: 129.2 | O12: 148.9 | P12: 142.1 | Q12: 153.2 | R12: 143 | S12: 134.8 | T12: 141.8 | U12: 138.6 | V12: 135.3 | W12: 134.4 | X12: 132.6 | Y12: 118.3 | Z12: 128.9 | AA12: 138.6 | AB12: 126.8 | AC12: 128.4 | AD12: 137.6
A13: Rural+Urban | B13: 2017 | C13: December | D13: 135.8 | E13: 143.3 | F13: 145.2 | G13: 141 | H13: 120.5 | I13: 141.5 | J13: 161.7 | K13: 129.1 | L13: 121.5 | M13: 137.1 | N13: 128.8 | O13: 149 | P13: 140.5 | Q13: 154.2 | R13: 143.1 | S13: 135.1 | T13: 142 | U13: 139.1 | V13: 136.6 | W13: 134.7 | X13: 133.1 | Y13: 118.5 | Z13: 129 | AA13: 138.5 | AB13: 126.5 | AC13: 128.6 | AD13: 137.2
... A39: Rural+Urban | B39: 2020 | C39: March | D39: 145.1 | E39: 167 | F39: 148.1 | G39: 151.5 | H39: 131.2 | I39: 142.5 | J39: 157.3 | K39: 141.1 | L39: 113.2 | M39: 153.2 | N39: 136.7 | O39: 159.6 | P39: 148.9 | Q39: 171.2 | R39: 151.2 | S39: 141.9 | T39: 149.8 | U39: 154.5 | V39: 148.9 | W39: 146.4 | X39: 152.3 | Y39: 129.9 | Z39: 143.7 | AA39: 156.1 | AB39: 145.2 | AC39: 143.8 | AD39: 148.6
A40: Rural+Urban | B40: 2020 | C40: April | D40: 148.7 | E40: NA | F40: 148.8 | G40: 155.6 | H40: 135.1 | I40: 149.9 | J40: 168.6 | K40: 150.4 | L40: 120.3 | M40: 157.1 | N40: 136.8 | O40: NA | P40: 151.4 | Q40: NA | R40: NA | S40: NA | T40: NA | U40: 155.6 | V40: 144.1 | W40: NA | X40: 150.7 | Y40: NA | Z40: NA | AA40: NA | AB40: NA | AC40: NA | AD40: NA
A41: Rural+Urban | B41: 2020 | C41: May | D41: NA | E41: NA | F41: NA | G41: NA | H41: NA | I41: NA | J41: NA | K41: NA | L41: NA | M41: NA | N41: NA | O41: NA | P41: NA | Q41: NA | R41: NA | S41: NA | T41: NA | U41: NA | V41: NA | W41: NA | X41: NA | Y41: NA | Z41: NA | AA41: NA | AB41: NA | AC41: NA | AD41: NA
A42: Rural+Urban | B42: 2020 | C42: June | D42: 149.6 | E42: 192.7 | F42: 151.4 | G42: 153.3 | H42: 136.3 | I42: 147.2 | J42: 156.5 | K42: 150.9 | L42: 114.2 | M42: 159.5 | N42: 139.4 | O42: 161.8 | P42: 154 | Q42: 183.5 | R42: 152.5 | S42: 144.4 | T42: 151.4 | U42: 154.7 | V42: 141.9 | W42: 146.4 | X42: 154.4 | Y42: 135 | Z42: 148.3 | AA42: 156.4 | AB42: 151.6 | AC42: 147 | AD42: 151.8
A43: Rural+Urban | B43: 2020 | C43: July | D43: 149.6 | E43: 192.7 | F43: 151.4 | G43: 153.3 | H43: 136.3 | I43: 147.2 | J43: 156.5 | K43: 150.9 | L43: 114.2 | M43: 159.5 | N43: 139.4 | O43: 161.8 | P43: 154 | Q43: 183.5 | R43: 152.5 | S43: 144.4 | T43: 151.4 | U43: 154.7 | V43: 141.9 | W43: 146.4 | X43: 154.4 | Y43: 135 | Z43: 148.3 | AA43: 156.4 | AB43: 151.6 | AC43: 147 | AD43: 151.8
A44: Rural+Urban | B44: 2020 | C44: August | D44: 148.9 | E44: 190.9 | F44: 150.8 | G44: 153.3 | H44: 137.4 | I44: 150.4 | J44: 178.1 | K44: 150.4 | L44: 115.1 | M44: 160 | N44: 140.6 | O44: 162.3 | P44: 157 | Q44: 182.6 | R44: 153.1 | S44: 143.4 | T44: 151.7 | U44: 155.5 | V44: 143 | W44: 148.4 | X44: 155 | Y44: 138.5 | Z44: 146 | AA44: 158.5 | AB44: 154.3 | AC44: 149 | AD44: 153.9
A45: Rural+Urban | B45: 2020 | C45: September | D45: 148.4 | E45: 187.1 | F45: 152.5 | G45: 153.6 | H45: 138.2 | I45: 150.9 | J45: 186.7 | K45: 149.8 | L45: 116.4 | M45: 160.3 | N45: 142.2 | O45: 162.9 | P45: 158 | Q45: 184.4 | R45: 153.4 | S45: 144.3 | T45: 152 | U45: 156.3 | V45: 142.9 | W45: 148.7 | X45: 155.6 | Y45: 139.6 | Z45: 146.6 | AA45: 157.5 | AB45: 158.4 | AC45: 150 | AD45: 154.7
A46: Rural+Urban | B46: 2020 | C46: October | D46: 147.5 | E46: 188.9 | F46: 161.4 | G46: 153.6 | H46: 140.1 | I46: 151.2 | J46: 209.2 | K46: 150.9 | L46: 116.2 | M46: 161 | N46: 144 | O46: 163.2 | P46: 161.4 | Q46: 184.3 | R46: 153.7 | S46: 144.6 | T46: 152.3 | U46: 156.5 | V46: 143.1 | W46: 148.7 | X46: 156.3 | Y46: 140.6 | Z46: 146.5 | AA46: 158.5 | AB46: 157 | AC46: 150.4 | AD46: 156.4
A47: Rural+Urban | B47: 2020 | C47: November | D47: 146.8 | E47: 191 | F47: 173.6 | G47: 153.8 | H47: 142.7 | I47: 148.4 | J47: 230 | K47: 156.8 | L47: 115.7 | M47: 161.8 | N47: 146.5 | O47: 163.8 | P47: 164.7 | Q47: 184.8 | R47: 154.3 | S47: 144.9 | T47: 152.8 | U47: 158 | V47: 143.6 | W47: 149.2 | X47: 157.2 | Y47: 140.4 | Z47: 148.4 | AA47: 158.6 | AB47: 156.9 | AC47: 150.7 | AD47: 158.4
A48: Rural+Urban | B48: 2020 | C48: December | D48: 146 | E48: 191 | F48: 175.3 | G48: 154.1 | H48: 146.6 | I48: 147.7 | J48: 230.5 | K48: 160.2 | L48: 115.3 | M48: 163 | N48: 149.2 | O48: 164.8 | P48: 165.4 | Q48: 185.4 | R48: 155 | S48: 145.4 | T48: 153.6 | U48: 158.4 | V48: 144.6 | W48: 149.7 | X48: 158.3 | Y48: 140.7 | Z48: 148.5 | AA48: 159.4 | AB48: 157.1 | AC48: 151.2 | AD48: 158.9
A49: Rural+Urban | B49: 2021 | C49: January | D49: 144.9 | E49: 190.1 | F49: 175.3 | G49: 154.1 | H49: 150.9 | I49: 149.6 | J49: 194.2 | K49: 160.4 | L49: 114.6 | M49: 164 | N49: 151.8 | O49: 165.6 | P49: 161 | Q49: 186.5 | R49: 155.5 | S49: 146.1 | T49: 154.2 | U49: 157.7 | V49: 147.9 | W49: 150 | X49: 159.3 | Y49: 141.9 | Z49: 149.6 | AA49: 159.2 | AB49: 156.8 | AC49: 151.9 | AD49: 157.3
A50: Rural+Urban | B50: 2021 | C50: February | D50: 144.3 | E50: 186.5 | F50: 168.7 | G50: 154.7 | H50: 158.7 | I50: 150.7 | J50: 160 | K50: 158.8 | L50: 112.8 | M50: 164.2 | N50: 155.5 | O50: 167.5 | P50: 156.9 | Q50: 188.3 | R50: 157.2 | S50: 147.4 | T50: 155.8 | U50: 159.8 | V50: 152.4 | W50: 150.9 | X50: 161.3 | Y50: 145.1 | Z50: 151.5 | AA50: 159.5 | AB50: 155.8 | AC50: 153.4 | AD50: 156.6
A51: Rural+Urban | B51: 2021 | C51: March | D51: 144.1 | E51: 192.2 | F51: 163.8 | G51: 154.9 | H51: 163.9 | I51: 153.7 | J51: 149.5 | K51: 159.8 | L51: 112.6 | M51: 163.5 | N51: 156.5 | O51: 168.2 | P51: 156.7 | Q51: 188.1 | R51: 157.8 | S51: 147.9 | T51: 156.4 | U51: 159.9 | V51: 155.5 | W51: 151.2 | X51: 161.7 | Y51: 146.2 | Z51: 152.6 | AA51: 160.2 | AB51: 153.8 | AC51: 153.8 | AD51: 156.8
A52: Rural+Urban | B52: 2021 | C52: April | D52: 144.3 | E52: 198 | F52: 164.6 | G52: 155.4 | H52: 170.1 | I52: 164.4 | J52: 144.1 | K52: 161.7 | L52: 113.1 | M52: 163.9 | N52: 157.6 | O52: 168.9 | P52: 158 | Q52: 188.8 | R52: 158.8 | S52: 148.5 | T52: 157.3 | U52: 161.4 | V52: 155.6 | W52: 151.8 | X52: 162.3 | Y52: 146.6 | Z52: 153.2 | AA52: 160.3 | AB52: 155.4 | AC52: 154.4 | AD52: 157.8
A53: Rural+Urban | B53: 2021 | C53: May | D53: 146.3 | E53: 200.5 | F53: 170.3 | G53: 156.1 | H53: 178.7 | I53: 167.1 | J53: 147.9 | K53: 165.4 | L53: 114.8 | M53: 168.2 | N53: 159.3 | O53: 170.4 | P53: 160.7 | Q53: 191.9 | R53: 161.8 | S53: 152.1 | T53: 160.4 | U53: 161.6 | V53: 159.4 | W53: 154.7 | X53: 165.8 | Y53: 148.9 | Z53: 155.8 | AA53: 161.2 | AB53: 158.6 | AC53: 156.8 | AD53: 160.4
... A72: Rural+Urban | B72: 2022 | C72: December | D72: 169.2 | E72: 209 | F72: 190.2 | G72: 173.6 | H72: 188.5 | I72: 158 | J72: 159.9 | K72: 170.8 | L72: 121.8 | M72: 205.2 | N72: 171 | O72: 190.3 | P72: 175.9 | Q72: 197.3 | R72: 184 | S72: 177 | T72: 183 | U72: 170.7 | V72: 182 | W72: 172.1 | X72: 181.1 | Y72: 163.4 | Z72: 168.9 | AA72: 174.1 | AB72: 175.8 | AC72: 172 | AD72: 175.7
A75: Year | B75: Month | C75: Sum of General index | D75: YoY% | F75: Year | G75: Inflation Rate (YoY%)
A76: 2017 | B76: January | C76: 130.3 | F76: 2017 | G76: 0.05295472
B77: December | C77: 137.2 | D77: =(GETPIVOTDATA("General index",$A$75,"Year",2017,"Month","December")-GETPIVOTDATA("General index",$A$75,"Year",2017,"Month","January"))/GETPIVOTDATA("General index",$A$75,"Year",2017,"Month","January") -> 0.05295472 | F77: 2018 | G77: 0.023374726
A78: 2018 | B78: January | C78: 136.9 | F78: 2019 | G78: 0.077363897
B79: December | C79: 140.1 | D79: =(GETPIVOTDATA("General index",$A$75,"Year",2018,"Month","December")-GETPIVOTDATA("General index",$A$75,"Year",2018,"Month","January"))/GETPIVOTDATA("General index",$A$75,"Year",2018,"Month","January") -> 0.023374726 | F79: 2020 | G79: 0.05792277
A80: 2019 | B80: January | C80: 139.6 | F80: 2021 | G80: 0.056579784
B81: December | C81: 150.4 | D81: =(GETPIVOTDATA("General index",$A$75,"Year",2019,"Month","December")-GETPIVOTDATA("General index",$A$75,"Year",2019,"Month","January"))/GETPIVOTDATA("General index",$A$75,"Year",2019,"Month","January") -> 0.077363897 | F81: 2022 | G81: 0.06035003
A82: 2020 | B82: January | C82: 150.2
B83: December | C83: 158.9 | D83: =(GETPIVOTDATA("General index",$A$75,"Year",2020,"Month","December")-GETPIVOTDATA("General index",$A$75,"Year",2020,"Month","January"))/GETPIVOTDATA("General index",$A$75,"Year",2020,"Month","January") -> 0.05792277
A84: 2021 | B84: January | C84: 157.3
B85: December | C85: 166.2 | D85: =(GETPIVOTDATA("General index",$A$75,"Year",2021,"Month","December")-GETPIVOTDATA("General index",$A$75,"Year",2021,"Month","January"))/GETPIVOTDATA("General index",$A$75,"Year",2021,"Month","January") -> 0.056579784
...

Sheet Problem.3
A1: Sector | B1: Year | C1: Month | D1: Cereals and products | E1: Meat and fish | F1: Egg | G1: Milk and products | H1: Oils and fats | I1: Fruits | J1: Vegetables | K1: Pulses and products | L1: Sugar and Confectionery | M1: Spices | N1: Prepared meals, snacks, sweets etc. | O1: Food and beverages | P1: MoM% | R1: Sector | S1: Year | T1: Month | U1: MoM% | X1: Month | Y1: Rural | Z1: Urban | AA1: Rural + Urban
A2: Rural | B2: 2022 | C2: May | D2: 152.9 | E2: 214.7 | F2: 161.4 | G2: 164.6 | H2: 209.9 | I2: 168 | J2: 160.4 | K2: 165 | L2: 118.9 | M2: 186.6 | N2: 180.4 | O2: 170.8 | R2: Rural | S2: 2022 | T2: October | U2: 0.010826211 | X2: January | Y2: 0.003440367 | Z2: 0.0050391937 | AA2: 0.0045480387
A3: Rural | B3: 2022 | C3: June | D3: 153.8 | E3: 217.2 | F3: 169.6 | G3: 165.4 | H3: 208.1 | I3: 165.8 | J3: 167.3 | K3: 164.6 | L3: 119.1 | M3: 188.9 | N3: 181.9 | O3: 172.4 | P3: =(O3-O2)/O2 -> 0.0093676815 | R3: Rural | S3: 2022 | T3: June | U3: 0.0093676815 | X3: February | Y3: -0.0011428571 | Z3: 0.0066852368 | AA3: 0.0016977929
A4: Rural | B4: 2022 | C4: July | D4: 155.2 | E4: 210.8 | F4: 174.3 | G4: 166.3 | H4: 202.2 | I4: 169.6 | J4: 168.6 | K4: 164.4 | L4: 119.2 | M4: 191.8 | N4: 183.1 | O4: 172.5 | P4: =(O4-O3)/O3 -> 0.0005800464 | R4: Rural | S4: 2022 | T4: September | U4: 0.0092006901 | X4: March | Y4: 0 | Z4: 0.00055340343 | AA4: 0
A5: Rural | B5: 2022 | C5: August | D5: 159.5 | E5: 204.1 | F5: 168.3 | G5: 167.9 | H5: 198.1 | I5: 169.2 | J5: 173.1 | K5: 167.1 | L5: 120.2 | M5: 195.6 | N5: 184 | O5: 173.9 | P5: =(O5-O4)/O4 -> 0.008115942 | R5: Rural | S5: 2022 | T5: August | U5: 0.008115942 | X5: April | Y5: 0.0040045767 | Z5: 0.0071902655 | AA5: 0.0050847458
A6: Rural | B6: 2022 | C6: September | D6: 162.9 | E6: 206.7 | F6: 169 | G6: 169.5 | H6: 194.1 | I6: 164.1 | J6: 176.9 | K6: 169 | L6: 120.8 | M6: 199.1 | N6: 184.8 | O6: 175.5 | P6: =(O6-O5)/O5 -> 0.0092006901 | R6: Rural | S6: 2023 | T6: May | U6: 0.0074074074 | X6: May | Y6: 0.0074074074 | Z6: 0.0054914882 | AA6: 0.0067453626
A7: Rural | B7: 2022 | C7: October | D7: 164.7 | E7: 208.8 | F7: 170.3 | G7: 170.9 | H7: 191.6 | I7: 162.2 | J7: 184.8 | K7: 169.7 | L7: 121.1 | M7: 201.6 | N7: 185.6 | O7: 177.4 | P7: =(O7-O6)/O6 -> 0.010826211 | R7: Rural | S7: 2023 | T7: April | U7: 0.0040045767 | X7: June | Y7: 0.0093676815 | Z7: 0.010140845 | AA7: 0.0092325447
A8: Rural | B8: 2022 | C8: November | D8: 166.9 | E8: 207.2 | F8: 180.2 | G8: 172.3 | H8: 194 | I8: 159.1 | J8: 171.6 | K8: 170.2 | L8: 121.5 | M8: 204.8 | N8: 186.9 | O8: 176.6 | P8: =(O8-O7)/O7 -> -0.0045095829 | R8: Rural | S8: 2023 | T8: January | U8: 0.003440367 | X8: July | Y8: 0.0005800464 | Z8: 0.00055772448 | AA8: 0.00057175529
A9: Rural | B9: 2022 | C9: December | D9: 168.8 | E9: 206.9 | F9: 189.1 | G9: 173.4 | H9: 193.9 | I9: 156.7 | J9: 150.2 | K9: 170.5 | L9: 121.2 | M9: 207.5 | N9: 187.7 | O9: 174.4 | P9: =(O9-O8)/O8 -> -0.012457531 | R9: Rural | S9: 2022 | T9: July | U9: 0.0005800464 | X9: August | Y9: 0.008115942 | Z9: 0.005574136 | AA9: 0.0074285714
A10: Rural | B10: 2023 | C10: January | D10: 174 | E10: 208.3 | F10: 192.9 | G10: 174.3 | H10: 192.6 | I10: 156.3 | J10: 142.9 | K10: 170.7 | L10: 120.3 | M10: 210.5 | N10: 188.5 | O10: 175 | P10: =(O10-O9)/O9 -> 0.003440367 | R10: Rural | S10: 2023 | T10: March | U10: 0 | X10: September | Y10: 0.0092006901 | Z10: 0.0077605322 | AA10: 0.0085082246
A11: Rural | B11: 2023 | C11: February | D11: 174.2 | E11: 205.2 | F11: 173.9 | G11: 177 | H11: 183.4 | I11: 167.2 | J11: 140.9 | K11: 170.4 | L11: 119.1 | M11: 212.1 | N11: 189.9 | O11: 174.8 | P11: =(O11-O10)/O10 -> -0.0011428571 | R11: Rural | S11: 2023 | T11: February | U11: -0.0011428571 | X11: October | Y11: 0.010826211 | Z11: 0.0082508251 | AA11: 0.010123735
A12: Rural | B12: 2023 | C12: March | D12: 174.3 | E12: 205.2 | F12: 173.9 | G12: 177 | H12: 183.3 | I12: 167.2 | J12: 140.9 | K12: 170.5 | L12: 119.1 | M12: 212.1 | N12: 189.9 | O12: 174.8 | P12: =(O12-O11)/O11 -> 0 | R12: Rural | S12: 2022 | T12: November | U12: -0.0045095829 | X12: November | Y12: -0.0045095829 | Z12: -0.010911075 | AA12: -0.0072383073
A13: Rural | B13: 2023 | C13: April | D13: 173.3 | E13: 206.9 | F13: 167.9 | G13: 178.2 | H13: 178.5 | I13: 173.7 | J13: 142.8 | K13: 172.8 | L13: 120.4 | M13: 215.5 | N13: 190.5 | O13: 175.5 | P13: =(O13-O12)/O12 -> 0.0040045767 | R13: Rural | S13: 2022 | T13: December | U13: -0.012457531 | X13: December | Y13: -0.012457531 | Z13: -0.014892443 | AA13: -0.01346046
A14: Rural | B14: 2023 | C14: May | D14: 173.2 | E14: 211.5 | F14: 171 | G14: 179.6 | H14: 173.3 | I14: 169 | J14: 148.7 | K14: 174.9 | L14: 121.9 | M14: 221 | N14: 191.1 | O14: 176.8 | P14: =(O14-O13)/O13 -> 0.0074074074
D15: =(D14-D3)/D3 -> 0.12613784 | E15: =(E14-E3)/E3 -> -0.026243094 | F15: =(F14-F3)/F3 -> 0.008254717 | G15: =(G14-G3)/G3 -> 0.085852479 | H15: =(H14-H3)/H3 -> -0.16722729 | I15: =(I14-I3)/I3 -> 0.019300362 | J15: =(J14-J3)/J3 -> -0.11117753 | K15: =(K14-K3)/K3 -> 0.062575942 | ... P15: =(P14-P3)/P3 -> -0.20925926
A18: Sector | B18: Year | C18: Month | D18: Cereals and products | E18: Meat and fish | F18: Egg | G18: Milk and products | H18: Oils and fats | I18: Fruits | J18: Vegetables | K18: Pulses and products | L18: Sugar and Confectionery | M18: Spices | N18: Prepared meals, snacks, sweets etc. | O18: Food and beverages | P18: MoM% | R18: Sector | S18: Year | T18: Month | U18: MoM% | X18: Category | Y18: Rural | Z18: Urban | AA18: Rural + Urban
A19: Urban | B19: 2022 | C19: May | D19: 156.7 | E19: 221.2 | F19: 164.1 | G19: 165.4 | H19: 189.5 | I19: 174.5 | J19: 203.2 | K19: 164.1 | L19: 121.2 | M19: 181.4 | N19: 184.9 | O19: 177.5 | R19: Urban | S19: 2022 | T19: June | U19: 0.010140845 | X19: Cereals and products | Y19: 0.12613784 | Z19: 0.10920635 | AA19: 0.12064516
A20: Urban | B20: 2022 | C20: June | D20: 157.5 | E20: 223.4 | F20: 172.8 | G20: 166.4 | H20: 188.6 | I20: 174.1 | J20: 211.5 | K20: 163.6 | L20: 121.4 | M20: 183.5 | N20: 186.3 | O20: 179.3 | P20: =(O20-O19)/O19 -> 0.010140845 | R20: Urban | S20: 2022 | T20: October | U20: 0.0082508251 | X20: Meat and fish | Y20: -0.026243094 | Z20: -0.017905103 | AA20: -0.023245214
A21: Urban | B21: 2022 | C21: July | D21: 159.3 | E21: 217.1 | F21: 176.6 | G21: 167.1 | H21: 184.8 | I21: 179.5 | J21: 208.5 | K21: 164 | L21: 121.5 | M21: 186.3 | N21: 187.7 | O21: 179.4 | P21: =(O21-O20)/O20 -> 0.00055772448 | R21: Urban | S21: 2022 | T21: September | U21: 0.0077605322 | X21: Egg | Y21: 0.008254717 | Z21: 0.022569444 | AA21: 0.014051522
A22: Urban | B22: 2022 | C22: August | D22: 162.1 | E22: 210.9 | F22: 170.6 | G22: 168.4 | H22: 182.5 | I22: 177.1 | J22: 213.1 | K22: 167.3 | L22: 122.2 | M22: 189.7 | N22: 188.9 | O22: 180.4 | P22: =(O22-O21)/O21 -> 0.005574136 | R22: Urban | S22: 2023 | T22: April | U22: 0.0071902655 | X22: Milk and products | Y22: 0.085852479 | Z22: 0.078125 | AA22: 0.082629674
A23: Urban | B23: 2022 | C23: September | D23: 164.9 | E23: 213.7 | F23: 170.9 | G23: 170.1 | H23: 179.3 | I23: 167.5 | J23: 220.8 | K23: 169.2 | L23: 123.1 | M23: 193.6 | N23: 190.4 | O23: 181.8 | P23: =(O23-O22)/O22 -> 0.0077605322 | R23: Urban | S23: 2023 | T23: February | U23: 0.0066852368 | X23: Oils and fats | Y23: -0.16722729 | Z23: -0.12831389 | AA23: -0.15380786
A24: Urban | B24: 2022 | C24: October | D24: 166.4 | E24: 214.9 | F24: 171.9 | G24: 171 | H24: 177.7 | I24: 165.7 | J24: 228.6 | K24: 169.9 | L24: 123.4 | M24: 196.4 | N24: 191.5 | O24: 183.3 | P24: =(O24-O23)/O23 -> 0.0082508251 | R24: Urban | S24: 2022 | T24: August | U24: 0.005574136 | X24: Fruits | Y24: 0.019300362 | Z24: 0.0097645032 | AA24: 0.01473188
A25: Urban | B25: 2022 | C25: November | D25: 168.4 | E25: 213.4 | F25: 183.2 | G25: 172.3 | H25: 180 | I25: 162.6 | J25: 205.5 | K25: 171 | L25: 123.4 | M25: 198.8 | N25: 192.4 | O25: 181.3 | P25: =(O25-O24)/O24 -> -0.010911075 | R25: Urban | S25: 2023 | T25: May | U25: 0.0054914882 | X25: Vegetables | Y25: -0.11117753 | Z25: -0.12529551 | AA25: -0.11684037
A26: Urban | B26: 2022 | C26: December | D26: 170.2 | E26: 212.9 | F26: 191.9 | G26: 173.9 | H26: 179.1 | I26: 159.5 | J26: 178.7 | K26: 171.3 | L26: 123.1 | M26: 200.5 | N26: 193.3 | O26: 178.6 | P26: =(O26-O25)/O25 -> -0.014892443 | R26: Urban | S26: 2023 | T26: January | U26: 0.0050391937 | X26: Pulses and products | Y26: 0.062575942 | Z26: 0.081295844 | AA26: 0.068776628
A27: Urban | B27: 2023 | C27: January | D27: 173.3 | E27: 215.2 | F27: 197 | G27: 175.2 | H27: 178 | I27: 160.5 | J27: 175.3 | K27: 171.2 | L27: 122.7 | M27: 204.3 | N27: 194.3 | O27: 179.5 | P27: =(O27-O26)/O26 -> 0.0050391937 | R27: Urban | S27: 2022 | T27: July | U27: 0.00055772448 | X27: Sugar and Confectionery | Y27: 0.023509656 | Z27: 0.02306425 | AA27: 0.023352794
A28: Urban | B28: 2023 | C28: February | D28: 174.7 | E28: 212.2 | F28: 177.2 | G28: 177.9 | H28: 172.2 | I28: 172.1 | J28: 175.8 | K28: 172.2 | L28: 121.9 | M28: 204.8 | N28: 196.6 | O28: 180.7 | P28: =(O28-O27)/O27 -> 0.0066852368 | R28: Urban | S28: 2023 | T28: March | U28: 0.00055340343 | X28: Spices | Y28: 0.16993118 | Z28: 0.15476839 | AA28: 0.16515232
A29: Urban | B29: 2023 | C29: March | D29: 174.7 | E29: 212.2 | F29: 177.2 | G29: 177.9 | H29: 172.2 | I29: 172.1 | J29: 175.9 | K29: 172.2 | L29: 121.9 | M29: 204.8 | N29: 196.6 | O29: 180.8 | P29: =(O29-O28)/O28 -> 0.00055340343 | R29: Urban | S29: 2022 | T29: November | U29: -0.010911075 | X29: Prepared meals, snacks, sweets etc. | Y29: 0.05057724 | Z29: 0.061191626 | AA29: 0.0560087
A30: Urban | B30: 2023 | C30: April | D30: 174.8 | E30: 213.7 | F30: 172.4 | G30: 178.8 | H30: 168.7 | I30: 179.2 | J30: 179.9 | K30: 174.7 | L30: 123.1 | M30: 207.8 | N30: 197 | O30: 182.1 | P30: =(O30-O29)/O29 -> 0.0071902655 | R30: Urban | S30: 2022 | T30: December | U30: -0.014892443 | X30: Food and beverages | Y30: 0.025522042 | Z30: 0.02119353 | AA30: 0.024013722
A31: Urban | B31: 2023 | C31: May | D31: 174.7 | E31: 219.4 | F31: 176.7 | G31: 179.4 | H31: 164.4 | I31: 175.8 | J31: 185 | K31: 176.9 | L31: 124.2 | M31: 211.9 | N31: 197.7 | O31: 183.1 | P31: =(O31-O30)/O30 -> 0.0054914882
D32: =(D31-D20)/D20 -> 0.10920635 | E32: =(E31-E20)/E20 -> -0.017905103 | F32: =(F31-F20)/F20 -> 0.022569444 | G32: =(G31-G20)/G20 -> 0.078125 | H32: =(H31-H20)/H20 -> -0.12831389 | I32: =(I31-I20)/I20 -> 0.0097645032 | J32: =(J31-J20)/J20 -> -0.12529551 | K32: =(K31-K20)/K20 -> 0.081295844 | ... P32: =(P31-P20)/P20 -> -0.45847825
A34: Sector | B34: Year | C34: Month | D34: Cereals and products | E34: Meat and fish | F34: Egg | G34: Milk and products | H34: Oils and fats | I34: Fruits | J34: Vegetables | K34: Pulses and products | L34: Sugar and Confectionery | M34: Spices | N34: Prepared meals, snacks, sweets etc. | O34: Food and beverages | P34: MoM% | R34: Sector | S34: Year | T34: Month | U34: MoM%
A35: Rural+Urban | B35: 2022 | C35: May | D35: 154.1 | E35: 217 | F35: 162.4 | G35: 164.9 | H35: 202.4 | I35: 171 | J35: 174.9 | K35: 164.7 | L35: 119.7 | M35: 184.9 | N35: 182.5 | O35: 173.3 | R35: Rural+Urban | S35: 2022 | T35: October | U35: 0.010123735
A36: Rural+Urban | B36: 2022 | C36: June | D36: 155 | E36: 219.4 | F36: 170.8 | G36: 165.8 | H36: 200.9 | I36: 169.7 | J36: 182.3 | K36: 164.3 | L36: 119.9 | M36: 187.1 | N36: 183.9 | O36: 174.9 | P36: =(O36-O35)/O35 -> 0.0092325447 | R36: Rural+Urban | S36: 2022 | T36: June | U36: 0.0092325447
A37: Rural+Urban | B37: 2022 | C37: July | D37: 156.5 | E37: 213 | F37: 175.2 | G37: 166.6 | H37: 195.8 | I37: 174.2 | J37: 182.1 | K37: 164.3 | L37: 120 | M37: 190 | N37: 185.2 | O37: 175 | P37: =(O37-O36)/O36 -> 0.00057175529 | R37: Rural+Urban | S37: 2022 | T37: September | U37: 0.0085082246
A38: Rural+Urban | B38: 2022 | C38: August | D38: 160.3 | E38: 206.5 | F38: 169.2 | G38: 168.1 | H38: 192.4 | I38: 172.9 | J38: 186.7 | K38: 167.2 | L38: 120.9 | M38: 193.6 | N38: 186.3 | O38: 176.3 | P38: =(O38-O37)/O37 -> 0.0074285714 | R38: Rural+Urban | S38: 2022 | T38: August | U38: 0.0074285714
A39: Rural+Urban | B39: 2022 | C39: September | D39: 163.5 | E39: 209.2 | F39: 169.7 | G39: 169.7 | H39: 188.7 | I39: 165.7 | J39: 191.8 | K39: 169.1 | L39: 121.6 | M39: 197.3 | N39: 187.4 | O39: 177.8 | P39: =(O39-O38)/O38 -> 0.0085082246 | R39: Rural+Urban | S39: 2023 | T39: May | U39: 0.0067453626
A40: Rural+Urban | B40: 2022 | C40: October | D40: 165.2 | E40: 210.9 | F40: 170.9 | G40: 170.9 | H40: 186.5 | I40: 163.8 | J40: 199.7 | K40: 169.8 | L40: 121.9 | M40: 199.9 | N40: 188.3 | O40: 179.6 | P40: =(O40-O39)/O39 -> 0.010123735 | R40: Rural+Urban | S40: 2023 | T40: April | U40: 0.0050847458
A41: Rural+Urban | B41: 2022 | C41: November | D41: 167.4 | E41: 209.4 | F41: 181.4 | G41: 172.3 | H41: 188.9 | I41: 160.7 | J41: 183.1 | K41: 170.5 | L41: 122.1 | M41: 202.8 | N41: 189.5 | O41: 178.3 | P41: =(O41-O40)/O40 -> -0.0072383073 | R41: Rural+Urban | S41: 2023 | T41: January | U41: 0.0045480387
A42: Rural+Urban | B42: 2022 | C42: December | D42: 169.2 | E42: 209 | F42: 190.2 | G42: 173.6 | H42: 188.5 | I42: 158 | J42: 159.9 | K42: 170.8 | L42: 121.8 | M42: 205.2 | N42: 190.3 | O42: 175.9 | P42: =(O42-O41)/O41 -> -0.01346046 | R42: Rural+Urban | S42: 2023 | T42: February | U42: 0.0016977929
A43: Rural+Urban | B43: 2023 | C43: January | D43: 173.8 | E43: 210.7 | F43: 194.5 | G43: 174.6 | H43: 187.2 | I43: 158.3 | J43: 153.9 | K43: 170.9 | L43: 121.1 | M43: 208.4 | N43: 191.2 | O43: 176.7 | P43: =(O43-O42)/O42 -> 0.0045480387 | R43: Rural+Urban | S43: 2022 | T43: July | U43: 0.00057175529
...

Sheet Problem.4
A1: Sector | B1: Year | C1: Month | D1: Food | E1: Health | F1: Essentital Services
A2: Rural | B2: 2017 | C2: January | D2: 1608.3 | E2: 129.9 | F2: 519
A3: Urban | B3: 2017 | C3: January | D3: 1590 | E3: 122.6 | F3: 620.3 | H3: Sector | I3: Year | J3: Average of Food | K3: Average of Health | L3: Average of Essentital Services | N3: Sector | O3: Category | P3: 2018 | Q3: 2019 | R3: 2020 | S3: 2021 | T3: 2022
A4: Rural+Urban | B4: 2017 | C4: January | D4: 1600.7 | E4: 127.1 | F4: 636.1 | H4: Rural | I4: 2017 | J4: 1633.075 | K4: 132.40833 | L4: 530.45 | N4: Rural | O4: Food | P4: 0.01492583 | Q4: 0.019084629 | R4: -0.020345463 | S4: 0.17426448 | T4: 0.059514773
A5: Rural | B5: 2017 | C5: February | D5: 1605.1 | E5: 130.1 | F5: 521.2 | I5: 2018 | J5: 1657.45 | K5: 140.125 | L5: 562.61667 | N5: Rural | O5: Health | P5: 0.058279313 | Q5: 0.086043305 | R5: 0.03864994 | S5: 0.069611395 | T5: 0.056930205
A6: Urban | B6: 2017 | C6: February | D6: 1581.9 | E6: 122.9 | F6: 622.9 | I6: 2019 | J6: 1689.0818 | K6: 152.18182 | L6: 586.77273 | N6: Rural | O6: Essentital Services | P6: 0.060640337 | Q6: 0.042935203 | R6: -0.12135203 | S6: 0.24376091 | T6: 0.069214675
A7: Rural+Urban | B7: 2017 | C7: February | D7: 1595.4 | E7: 127.4 | F7: 638.9 | I7: 2020 | J7: 1654.7167 | K7: 158.06364 | L7: 515.56667 | N7: Rural+Urban | O7: Food | P7: 0.0099840604 | Q7: 0.034342737 | R7: -0.018194615 | S7: 0.1754215 | T7: 0.05879102
A8: Rural | B8: 2017 | C8: March | D8: 1598.7 | E8: 130.6 | F8: 523.3 | I8: 2021 | J8: 1943.075 | K8: 169.06667 | L8: 641.24167 | N8: Rural+Urban | O8: Health | P8: 0.062077839 | Q8: 0.074588404 | R8: 0.043534403 | S8: 0.074926836 | T8: 0.060800965
A9: Urban | B9: 2017 | C9: March | D9: 1582.1 | E9: 123.1 | F9: 625.9 | I9: 2022 | J9: 2058.7167 | K9: 178.69167 | L9: 685.625 | N9: Rural+Urban | O9: Essentital Services | P9: 0.061327413 | Q9: 0.036261411 | R9: -0.10041538 | S9: 0.22710057 | T9: 0.066496137
A10: Rural+Urban | B10: 2017 | C10: March | D10: 1591.7 | E10: 127.8 | F10: 641.7 | H10: Rural+Urban | I10: 2017 | J10: 1625.925 | K10: 129.54167 | L10: 649.38333 | N10: Urban | O10: Food | P10: 0.00011339271 | Q10: 0.061066764 | R10: -0.014868684 | S10: 0.17704831 | T10: 0.057963608
A11: Rural | B11: 2017 | C11: April | D11: 1596.3 | E11: 131 | F11: 524.2 | I11: 2018 | J11: 1642.1583 | K11: 137.58333 | L11: 689.20833 | N11: Urban | O11: Health | P11: 0.067605446 | Q11: 0.05578887 | R11: 0.052060457 | S11: 0.083870539 | T11: 0.068227842
A12: Urban | B12: 2017 | C12: April | D12: 1584.3 | E12: 123.4 | F12: 627 | I12: 2019 | J12: 1698.5545 | K12: 147.84545 | L12: 714.2 | N12: Urban | O12: Essentital Services | P12: 0.057976371 | Q12: 0.02993023 | R12: -0.09069894 | S12: 0.23769301 | T12: 0.070290635
A13: Rural+Urban | B13: 2017 | C13: April | D13: 1591 | E13: 128.1 | F13: 643 | I13: 2020 | J13: 1667.65 | K13: 154.28182 | L13: 642.48333
A14: Rural | B14: 2017 | C14: May | D14: 1597.2 | E14: 131.4 | F14: 525.6 | I14: 2021 | J14: 1960.1917 | K14: 165.84167 | L14: 788.39167
A15: Urban | B15: 2017 | C15: May | D15: 1585.8 | E15: 123.6 | F15: 626.8 | I15: 2022 | J15: 2075.4333 | K15: 175.925 | L15: 840.81667
A16: Rural+Urban | B16: 2017 | C16: May | D16: 1592 | E16: 128.4 | F16: 643.9 | H16: Urban | I16: 2017 | J16: 1616.8 | K16: 124.86667 | L16: 631.29167
A17: Rural | B17: 2017 | C17: June | D17: 1608.4 | E17: 131.3 | F17: 526.3 | I17: 2018 | J17: 1616.9833 | K17: 133.30833 | L17: 667.89167
A18: Urban | B18: 2017 | C18: June | D18: 1606.8 | E18: 123.8 | F18: 625.4 | I18: 2019 | J18: 1715.7273 | K18: 140.74545 | L18: 687.88182
A19: Rural+Urban | B19: 2017 | C19: June | D19: 1606.9 | E19: 128.5 | F19: 643.3 | I19: 2020 | J19: 1690.2167 | K19: 148.07273 | L19: 625.49167
A20: Rural | B20: 2017 | C20: July | D20: 1641.5 | E20: 132.1 | F20: 529.1 | I20: 2021 | J20: 1989.4667 | K20: 160.49167 | L20: 774.16667
A21: Urban | B21: 2017 | C21: July | D21: 1643.7 | E21: 125 | F21: 628.2 | I21: 2022 | J21: 2104.7833 | K21: 171.44167 | L21: 828.58333
A22: Rural+Urban | B22: 2017 | C22: July | D22: 1640.9 | E22: 129.4 | F22: 646.7 | H22: Grand Total | J22: 1781.1113 | K22: 151.16476 | L22: 670.21549
A23: Rural | B23: 2017 | C23: August | D23: 1660.9 | E23: 133 | F23: 534.2
A24: Urban | B24: 2017 | C24: August | D24: 1648.4 | E24: 125.7 | F24: 631.3
A25: Rural+Urban | B25: 2017 | C25: August | D25: 1655.1 | E25: 130.2 | F25: 651.9
A26: Rural | B26: 2017 | C26: September | D26: 1652.6 | E26: 133.4 | F26: 536.1 | H26: Sector | I26: Year | J26: Average of Food | K26: Average of Health | L26: Average of Essentital Services | M26: Inflation of Food | N26: Inflation of Health | O26: Inflation of Essentital Services
A27: Urban | B27: 2017 | C27: September | D27: 1624.9 | E27: 126.1 | F27: 636 | H27: Rural | I27: 2017 | J27: 1633.075 | K27: 132.40833 | L27: 530.45
A28: Rural+Urban | B28: 2017 | C28: September | D28: 1641.2 | E28: 130.6 | F28: 655.7 | I28: 2018 | J28: 1657.45 | K28: 140.125 | L28: 562.61667 | M28: =(J28-J27)/J27 -> 0.01492583 | N28: =(K28-K27)/K27 -> 0.058279313 | O28: =(L28-L27)/L27 -> 0.060640337
A29: Rural | B29: 2017 | C29: October | D29: 1659.6 | E29: 134.2 | F29: 537.6 | I29: 2019 | J29: 1689.0818 | K29: 152.18182 | L29: 586.77273 | M29: =(J29-J28)/J28 -> 0.019084629 | N29: =(K29-K28)/K28 -> 0.086043305 | O29: =(L29-L28)/L28 -> 0.042935203
A30: Urban | B30: 2017 | C30: October | D30: 1640.6 | E30: 126.6 | F30: 639.5 | I30: 2020 | J30: 1654.7167 | K30: 158.06364 | L30: 515.56667 | M30: =(J30-J29)/J29 -> -0.020345463 | N30: =(K30-K29)/K29 -> 0.03864994 | O30: =(L30-L29)/L29 -> -0.12135203
A31: Rural+Urban | B31: 2017 | C31: October | D31: 1651 | E31: 131.3 | F31: 658.8 | I31: 2021 | J31: 1943.075 | K31: 169.06667 | L31: 641.24167 | M31: =(J31-J30)/J30 -> 0.17426448 | N31: =(K31-K30)/K30 -> 0.069611395 | O31: =(L31-L30)/L30 -> 0.24376091
A32: Rural | B32: 2017 | C32: November | D32: 1685.8 | E32: 135.8 | F32: 543.6 | I32: 2022 | J32: 2058.7167 | K32: 178.69167 | L32: 685.625 | M32: =(J32-J31)/J31 -> 0.059514773 | N32: =(K32-K31)/K31 -> 0.056930205 | O32: =(L32-L31)/L31 -> 0.069214675
A33: Urban | B33: 2017 | C33: November | D33: 1671.3 | E33: 127.4 | F33: 645 | H33: Rural+Urban | I33: 2017 | J33: 1625.925 | K33: 129.54167 | L33: 649.38333
A34: Rural+Urban | B34: 2017 | C34: November | D34: 1679 | E34: 132.6 | F34: 665.2 | I34: 2018 | J34: 1642.1583 | K34: 137.58333 | L34: 689.20833 | M34: =(J34-J33)/J33 -> 0.0099840604 | N34: =(K34-K33)/K33 -> 0.062077839 | O34: =(L34-L33)/L33 -> 0.061327413
A35: Rural | B35: 2017 | C35: December | D35: 1682.5 | E35: 136.1 | F35: 545.2 | I35: 2019 | J35: 1698.5545 | K35: 147.84545 | L35: 714.2 | M35: =(J35-J34)/J34 -> 0.034342737 | N35: =(K35-K34)/K34 -> 0.074588404 | O35: =(L35-L34)/L34 -> 0.036261411
A36: Urban | B36: 2017 | C36: December | D36: 1641.8 | E36: 128.2 | F36: 647.2 | I36: 2020 | J36: 1667.65 | K36: 154.28182 | L36: 642.48333 | M36: =(J36-J35)/J35 -> -0.018194615 | N36: =(K36-K35)/K35 -> 0.043534403 | O36: =(L36-L35)/L35 -> -0.10041538
A37: Rural+Urban | B37: 2017 | C37: December | D37: 1666.2 | E37: 133.1 | F37: 667.4 | I37: 2021 | J37: 1960.1917 | K37: 165.84167 | L37: 788.39167 | M37: =(J37-J36)/J36 -> 0.1754215 | N37: =(K37-K36)/K36 -> 0.074926836 | O37: =(L37-L36)/L36 -> 0.22710057
A38: Rural | B38: 2018 | C38: January | D38: 1669.5 | E38: 136 | F38: 546.4 | I38: 2022 | J38: 2075.4333 | K38: 175.925 | L38: 840.81667 | M38: =(J38-J37)/J37 -> 0.05879102 | N38: =(K38-K37)/K37 -> 0.060800965 | O38: =(L38-L37)/L37 -> 0.066496137
A39: Urban | B39: 2018 | C39: January | D39: 1622.4 | E39: 129 | F39: 650.6 | H39: Urban | I39: 2017 | J39: 1616.8 | K39: 124.86667 | L39: 631.29167
